Workbook

Sheet Opdracht
A1: Opdracht:
A2: Dit Excel overzicht bevat een verzameling meterstanden van Gas, Water en Elektra verbruik.
A4: Bekijk de verschillende werkbladen.
A5: Op het werkblad Meterstanden staat alle data. Op de andere werkbladen wordt hier naar verwezen.
A7: Maak de verschillende grafieken van de werkbladen Jaarverbruik, Grafiek Elektra, Grafiek Gas en Grafiek Water na. Maak deze op eigen nieuwe werkbladen. (Laat de originele werkbladen staan.)
A9: Inmiddels is er een jaar aan data bij.
A10: Pas alle bestaande data en grafieken aan zodat ook het laatste jaar zichtbaar is in de grafieken.
A11: Voeg aan de grafieken een trendlijn toe.
A12: Filter de gegevens zodanig dat je alleen de jaren 2020 en 2024 laat zien.

Sheet Meterstanden
B1: Meterstanden | I1: maand Verbruik | Q1: jaar Verbruik
B2: Elektr. 1 Laag tarief | C2: Elektr. 2 Normaal tarief | D2: terug laag | E2: terug normaal | F2: Gas | G2: Water | H2: Datum | I2: Elektr. 1 Laag tarief | J2: Elektr. 2 Normaal tarief | K2: E. Totaal | L2: terug laag | M2: terug normaal | N2: Gas | O2: Water | Q2: Elektr. 1 | R2: Elektr. 2 | S2: E. Totaal | T2: Gas | U2: Water
B3: 2014 | I3: 2014 | Q3: 2014
A4: 41640 | B4: 0 | C4: 35429 | F4: 37113 | G4: 1316 | H4: =A4 -> 41640 | I4: =IF(B5="","",B5-B4) -> 0 | J4: =IF(C5="","",C5-C4) -> 267 | K4: =IF(I4="","",I4+J4) -> 267 | N4: =IF(F5="","",F5-F4) -> 226 | O4: =IF(G5="","",G5-G4) -> 11
A5: 41671 | B5: 0 | C5: 35696 | F5: 37339 | G5: 1327 | H5: =A5 -> 41671 | I5: =IF(B6="","",B6-B5) -> 0 | J5: =IF(C6="","",C6-C5) -> 272 | K5: =IF(I5="","",I5+J5) -> 272 | N5: =IF(F6="","",F6-F5) -> 161 | O5: =IF(G6="","",G6-G5) -> 13
A6: 41699 | B6: 0 | C6: 35968 | F6: 37500 | G6: 1340 | H6: =A6 -> 41699 | I6: =IF(B7="","",B7-B6) -> 0 | J6: =IF(C7="","",C7-C6) -> 355 | K6: =IF(I6="","",I6+J6) -> 355 | N6: =IF(F7="","",F7-F6) -> 117 | O6: =IF(G7="","",G7-G6) -> 11
A7: 41730 | B7: 0 | C7: 36323 | F7: 37617 | G7: 1351 | H7: =A7 -> 41730 | I7: =IF(B8="","",B8-B7) -> 0 | J7: =IF(C8="","",C8-C7) -> 184 | K7: =IF(I7="","",I7+J7) -> 184 | N7: =IF(F8="","",F8-F7) -> 47 | O7: =IF(G8="","",G8-G7) -> 13
A8: 41760 | B8: 0 | C8: 36507 | F8: 37664 | G8: 1364 | H8: =A8 -> 41760 | I8: =IF(B9="","",B9-B8) -> 0 | J8: =IF(C9="","",C9-C8) -> 282 | K8: =IF(I8="","",I8+J8) -> 282 | N8: =IF(F9="","",F9-F8) -> 38 | O8: =IF(G9="","",G9-G8) -> 14
A9: 41791 | B9: 0 | C9: 36789 | F9: 37702 | G9: 1378 | H9: =A9 -> 41791 | I9: =IF(B10="","",B10-B9) -> 0 | J9: =IF(C10="","",C10-C9) -> 282 | K9: =IF(I9="","",I9+J9) -> 282 | N9: =IF(F10="","",F10-F9) -> 35 | O9: =IF(G10="","",G10-G9) -> 14
A10: 41821 | B10: 0 | C10: 37071 | F10: 37737 | G10: 1392 | H10: =A10 -> 41821 | I10: =IF(B11="","",B11-B10) -> 0 | J10: =IF(C11="","",C11-C10) -> 282 | K10: =IF(I10="","",I10+J10) -> 282 | N10: =IF(F11="","",F11-F10) -> 28 | O10: =IF(G11="","",G11-G10) -> 12
A11: 41852 | B11: 0 | C11: 37353 | F11: 37765 | G11: 1404 | H11: =A11 -> 41852 | I11: =IF(B12="","",B12-B11) -> 0 | J11: =IF(C12="","",C12-C11) -> 304 | K11: =IF(I11="","",I11+J11) -> 304 | N11: =IF(F12="","",F12-F11) -> 26 | O11: =IF(G12="","",G12-G11) -> 11
A12: 41883 | B12: 0 | C12: 37657 | F12: 37791 | G12: 1415 | H12: =A12 -> 41883 | I12: =IF(B13="","",B13-B12) -> 0 | J12: =IF(C13="","",C13-C12) -> 273 | K12: =IF(I12="","",I12+J12) -> 273 | N12: =IF(F13="","",F13-F12) -> 27 | O12: =IF(G13="","",G13-G12) -> 10
A13: 41913 | B13: 0 | C13: 37930 | F13: 37818 | G13: 1425 | H13: =A13 -> 41913 | I13: =IF(B14="","",B14-B13) -> 0 | J13: =IF(C14="","",C14-C13) -> 304 | K13: =IF(I13="","",I13+J13) -> 304 | N13: =IF(F14="","",F14-F13) -> 46 | O13: =IF(G14="","",G14-G13) -> 12
A14: 41944 | B14: 0 | C14: 38234 | F14: 37864 | G14: 1437 | H14: =A14 -> 41944 | I14: =IF(B15="","",B15-B14) -> 0 | J14: =IF(C15="","",C15-C14) -> 355 | K14: =IF(I14="","",I14+J14) -> 355 | N14: =IF(F15="","",F15-F14) -> 199 | O14: =IF(G15="","",G15-G14) -> 13
A15: 41974 | B15: 0 | C15: 38589 | F15: 38063 | G15: 1450 | H15: =A15 -> 41974 | I15: =IF(B17="","",B17-B15) -> 0 | J15: =IF(C17="","",C17-C15) -> 349 | K15: =IF(I15="","",I15+J15) -> 349 | N15: =IF(F17="","",F17-F15) -> 140 | O15: =IF(G17="","",G17-G15) -> 11 | Q15: =SUM(I4:I15) -> 0 | R15: =SUM(J4:J15) -> 3509 | S15: =SUM(K4:K15) -> 3509 | T15: =SUM(N4:N15) -> 1090 | U15: =SUM(O4:O15) -> 145
B16: 2015 | I16: 2015 | Q16: 2015
A17: 42005 | B17: 0 | C17: 38938 | F17: 38203 | G17: 1461 | H17: =A17 -> 42005 | I17: =IF(B18="","",B18-B17) -> 0 | J17: =IF(C18="","",C18-C17) -> 335 | K17: =IF(I17="","",I17+J17) -> 335 | N17: =IF(F18="","",F18-F17) -> 288 | O17: =IF(G18="","",G18-G17) -> 12
A18: 42036 | B18: 0 | C18: 39273 | F18: 38491 | G18: 1473 | H18: =A18 -> 42036 | I18: =IF(B19="","",B19-B18) -> 0 | J18: =IF(C19="","",C19-C18) -> 269 | K18: =IF(I18="","",I18+J18) -> 269 | N18: =IF(F19="","",F19-F18) -> 194 | O18: =IF(G19="","",G19-G18) -> 10
A19: 42064 | B19: 0 | C19: 39542 | F19: 38685 | G19: 1483 | H19: =A19 -> 42064 | I19: =IF(B20="","",B20-B19) -> 0 | J19: =IF(C20="","",C20-C19) -> 302 | K19: =IF(I19="","",I19+J19) -> 302 | N19: =IF(F20="","",F20-F19) -> 199 | O19: =IF(G20="","",G20-G19) -> 11
A20: 42095 | B20: 0 | C20: 39844 | F20: 38884 | G20: 1494 | H20: =A20 -> 42095 | I20: =IF(B21="","",B21-B20) -> 0 | J20: =IF(C21="","",C21-C20) -> 272 | K20: =IF(I20="","",I20+J20) -> 272 | N20: =IF(F21="","",F21-F20) -> 81 | O20: =IF(G21="","",G21-G20) -> 10
A21: 42125 | B21: 0 | C21: 40116 | F21: 38965 | G21: 1504 | H21: =A21 -> 42125 | I21: =IF(B22="","",B22-B21) -> 0 | J21: =IF(C22="","",C22-C21) -> 305 | K21: =IF(I21="","",I21+J21) -> 305 | N21: =IF(F22="","",F22-F21) -> 50 | O21: =IF(G22="","",G22-G21) -> 12
A22: 42156 | B22: 0 | C22: 40421 | F22: 39015 | G22: 1516 | H22: =A22 -> 42156 | I22: =IF(B23="","",B23-B22) -> 0 | J22: =IF(C23="","",C23-C22) -> 290 | K22: =IF(I22="","",I22+J22) -> 290 | N22: =IF(F23="","",F23-F22) -> 32 | O22: =IF(G23="","",G23-G22) -> 12
A23: 42186 | B23: 0 | C23: 40711 | F23: 39047 | G23: 1528 | H23: =A23 -> 42186 | I23: =IF(B24="","",B24-B23) -> 0 | J23: =IF(C24="","",C24-C23) -> 209 | K23: =IF(I23="","",I23+J23) -> 209 | N23: =IF(F24="","",F24-F23) -> 18 | O23: =IF(G24="","",G24-G23) -> 8
A24: 42217 | B24: 0 | C24: 40920 | F24: 39065 | G24: 1536 | H24: =A24 -> 42217 | I24: =IF(B25="","",B25-B24) -> 0 | J24: =IF(C25="","",C25-C24) -> 293 | K24: =IF(I24="","",I24+J24) -> 293 | N24: =IF(F25="","",F25-F24) -> 36 | O24: =IF(G25="","",G25-G24) -> 12
A25: 42248 | B25: 0 | C25: 41213 | F25: 39101 | G25: 1548 | H25: =A25 -> 42248 | I25: =IF(B26="","",B26-B25) -> 0 | J25: =IF(C26="","",C26-C25) -> 293 | K25: =IF(I25="","",I25+J25) -> 293 | N25: =IF(F26="","",F26-F25) -> 37 | O25: =IF(G26="","",G26-G25) -> 12
A26: 42278 | B26: 0 | C26: 41506 | F26: 39138 | G26: 1560 | H26: =A26 -> 42278 | I26: =IF(B27="","",B27-B26) -> 0 | J26: =IF(C27="","",C27-C26) -> 304 | K26: =IF(I26="","",I26+J26) -> 304 | N26: =IF(F27="","",F27-F26) -> 88 | O26: =IF(G27="","",G27-G26) -> 14
A27: 42309 | B27: 0 | C27: 41810 | F27: 39226 | G27: 1574 | H27: =A27 -> 42309 | I27: =IF(B28="","",B28-B27) -> 0 | J27: =IF(C28="","",C28-C27) -> 303 | K27: =IF(I27="","",I27+J27) -> 303 | N27: =IF(F28="","",F28-F27) -> 95 | O27: =IF(G28="","",G28-G27) -> 13
A28: 42339 | B28: 0 | C28: 42113 | F28: 39321 | G28: 1587 | H28: =A28 -> 42339 | I28: =IF(B30="","",B30-B28) -> 0 | J28: =IF(C30="","",C30-C28) -> 369 | K28: =IF(I28="","",I28+J28) -> 369 | N28: =IF(F30="","",F30-F28) -> 107 | O28: =IF(G30="","",G30-G28) -> 14 | Q28: =SUM(I17:I28) -> 0 | R28: =SUM(J17:J28) -> 3544 | S28: =SUM(K17:K28) -> 3544 | T28: =SUM(N17:N28) -> 1225 | U28: =SUM(O17:O28) -> 140
B29: 2016 | I29: 2016 | Q29: 2016
A30: 42370 | B30: 0 | C30: 42482 | F30: 39428 | G30: 1601 | H30: =A30 -> 42370 | I30: =IF(B31="","",B31-B30) -> 0 | J30: =IF(C31="","",C31-C30) -> 317 | K30: =IF(I30="","",I30+J30) -> 317 | N30: =IF(F31="","",F31-F30) -> 220 | O30: =IF(G31="","",G31-G30) -> 14
A31: 42401 | B31: 0 | C31: 42799 | F31: 39648 | G31: 1615 | H31: =A31 -> 42401 | I31: =IF(B32="","",B32-B31) -> 0 | J31: =IF(C32="","",C32-C31) -> 274 | K31: =IF(I31="","",I31+J31) -> 274 | N31: =IF(F32="","",F32-F31) -> 192 | O31: =IF(G32="","",G32-G31) -> 13
A32: 42430 | B32: 0 | C32: 43073 | F32: 39840 | G32: 1628 | H32: =A32 -> 42430 | I32: =IF(B33="","",B33-B32) -> 0 | J32: =IF(C33="","",C33-C32) -> 268 | K32: =IF(I32="","",I32+J32) -> 268 | N32: =IF(F33="","",F33-F32) -> 175 | O32: =IF(G33="","",G33-G32) -> 13
A33: 42461 | B33: 0 | C33: 43341 | F33: 40015 | G33: 1641 | H33: =A33 -> 42461 | I33: =IF(B34="","",B34-B33) -> 0 | J33: =IF(C34="","",C34-C33) -> 265 | K33: =IF(I33="","",I33+J33) -> 265 | N33: =IF(F34="","",F34-F33) -> 117 | O33: =IF(G34="","",G34-G33) -> 14
A34: 42491 | B34: 0 | C34: 43606 | F34: 40132 | G34: 1655 | H34: =A34 -> 42491 | I34: =IF(B35="","",B35-B34) -> 0 | J34: =IF(C35="","",C35-C34) -> 271 | K34: =IF(I34="","",I34+J34) -> 271 | N34: =IF(F35="","",F35-F34) -> 48 | O34: =IF(G35="","",G35-G34) -> 14
A35: 42522 | B35: 0 | C35: 43877 | F35: 40180 | G35: 1669 | H35: =A35 -> 42522 | I35: =IF(B36="","",B36-B35) -> 0 | J35: =IF(C36="","",C36-C35) -> 260 | K35: =IF(I35="","",I35+J35) -> 260 | N35: =IF(F36="","",F36-F35) -> 34 | O35: =IF(G36="","",G36-G35) -> 13
A36: 42552 | B36: 0 | C36: 44137 | F36: 40214 | G36: 1682 | H36: =A36 -> 42552 | I36: =IF(B37="","",B37-B36) -> 0 | J36: =IF(C37="","",C37-C36) -> 254 | K36: =IF(I36="","",I36+J36) -> 254 | N36: =IF(F37="","",F37-F36) -> 25 | O36: =IF(G37="","",G37-G36) -> 12
A37: 42583 | B37: 0 | C37: 44391 | F37: 40239 | G37: 1694 | H37: =A37 -> 42583 | I37: =IF(B38="","",B38-B37) -> 0 | J37: =IF(C38="","",C38-C37) -> 305 | K37: =IF(I37="","",I37+J37) -> 305 | N37: =IF(F38="","",F38-F37) -> 34 | O37: =IF(G38="","",G38-G37) -> 17
A38: 42614 | B38: 0 | C38: 44696 | F38: 40273 | G38: 1711 | H38: =A38 -> 42614 | I38: =IF(B39="","",B39-B38) -> 0 | J38: =IF(C39="","",C39-C38) -> 280 | K38: =IF(I38="","",I38+J38) -> 280 | N38: =IF(F39="","",F39-F38) -> 29 | O38: =IF(G39="","",G39-G38) -> 12
A39: 42644 | B39: 0 | C39: 44976 | F39: 40302 | G39: 1723 | H39: =A39 -> 42644 | I39: =IF(B40="","",B40-B39) -> 0 | J39: =IF(C40="","",C40-C39) -> 275 | K39: =IF(I39="","",I39+J39) -> 275 | N39: =IF(F40="","",F40-F39) -> 105 | O39: =IF(G40="","",G40-G39) -> 15
A40: 42675 | B40: 0 | C40: 45251 | F40: 40407 | G40: 1738 | H40: =A40 -> 42675 | I40: =IF(B41="","",B41-B40) -> 0 | J40: =IF(C41="","",C41-C40) -> 283 | K40: =IF(I40="","",I40+J40) -> 283 | N40: =IF(F41="","",F41-F40) -> 155 | O40: =IF(G41="","",G41-G40) -> 18
...

Sheet Jaarverbuik
A1: Jaar | B1: Elektra Laag | C1: Elektra Hoog | D1: Elektra totaal | E1: Gas | F1: Water | G1: terug laag | H1: Terug hoog | I1: terug totaal
A2: 2014 | B2: =Meterstanden!Q15 -> 0 | C2: =Meterstanden!R15 -> 3509 | D2: =Meterstanden!S15 -> 3509 | E2: =Meterstanden!T15 -> 1090 | F2: =Meterstanden!U15 -> 145
A3: 2015 | B3: =Meterstanden!Q28 -> 0 | C3: =Meterstanden!R28 -> 3544 | D3: =Meterstanden!S28 -> 3544 | E3: =Meterstanden!T28 -> 1225 | F3: =Meterstanden!U28 -> 140
A4: 2016 | B4: =Meterstanden!Q41 -> 0 | C4: =Meterstanden!R41 -> 3369 | D4: =Meterstanden!S41 -> 3369 | E4: =Meterstanden!T41 -> 1294 | F4: =Meterstanden!U41 -> 171
A5: 2017 | B5: =Meterstanden!Q54 -> 861 | C5: =Meterstanden!R54 -> 1927 | D5: =Meterstanden!S54 -> 2899 | E5: =Meterstanden!T54 -> 1335 | F5: =Meterstanden!U54 -> 109
A6: 2018 | B6: =Meterstanden!Q67 -> 1783 | C6: =Meterstanden!R67 -> 1547 | D6: =Meterstanden!S67 -> 3330 | E6: =Meterstanden!T67 -> 1161 | F6: =Meterstanden!U67 -> 86
A7: 2019 | B7: =Meterstanden!Q80 -> 1796 | C7: =Meterstanden!R80 -> 1621 | D7: =Meterstanden!S80 -> 3417 | E7: =Meterstanden!T80 -> 1316 | F7: =Meterstanden!U80 -> 97
A8: 2020 | B8: =Meterstanden!Q93 -> 1778 | C8: =Meterstanden!R93 -> 1793 | D8: =Meterstanden!S93 -> 3571 | E8: =Meterstanden!T93 -> 1266 | F8: =Meterstanden!U93 -> 112
A9: 2021 | B9: =Meterstanden!Q106 -> 1823 | C9: =Meterstanden!R106 -> 1931 | D9: =Meterstanden!S106 -> 3754 | E9: =Meterstanden!T106 -> 988 | F9: =Meterstanden!U106 -> 107
A10: 2022 | B10: =Meterstanden!Q119 -> 1839 | C10: =Meterstanden!R119 -> 1693 | D10: =Meterstanden!S119 -> 3532 | E10: =Meterstanden!T119 -> 557 | F10: =Meterstanden!U119 -> 92
A11: 2023 | B11: =Meterstanden!Q132 -> 1422 | C11: =Meterstanden!R132 -> 1299 | D11: =Meterstanden!S132 -> 2721 | E11: =Meterstanden!T132 -> 394 | F11: =Meterstanden!U132 -> 69 | G11: =Meterstanden!Q131 -> 332 | H11: =Meterstanden!R131 -> 993 | I11: =Meterstanden!S131 -> 1325

Sheet Vergelijking per maand
B1: Elektra Totaal
B2: 2014 | C2: 2015 | D2: 2016 | E2: 2017 | F2: 2018 | G2: 2019 | H2: 2020 | I2: 2021 | J2: 2022 | K2: 2023 | L2: 2024
A3: Januari | B3: =Meterstanden!K4 -> 267 | C3: =Meterstanden!K17 -> 335 | D3: =Meterstanden!K30 -> 317 | E3: =Meterstanden!K43 -> 269 | F3: =Meterstanden!K56 -> 292 | G3: =Meterstanden!K69 -> 343 | H3: =Meterstanden!K82 -> 353 | I3: =Meterstanden!K95 -> 199 | J3: =Meterstanden!K108 -> 430 | K3: =Meterstanden!K121 -> 362 | L3: =Meterstanden!K134 -> 340
A4: Februari | B4: =Meterstanden!K5 -> 272 | C4: =Meterstanden!K18 -> 269 | D4: =Meterstanden!K31 -> 274 | E4: =Meterstanden!K44 -> 276 | F4: =Meterstanden!K57 -> 290 | G4: =Meterstanden!K70 -> 303 | H4: =Meterstanden!K83 -> 373 | I4: 363 | J4: =Meterstanden!K109 -> 373 | K4: =Meterstanden!K122 -> 298 | L4: =Meterstanden!K135 -> 241
A5: Maart | B5: =Meterstanden!K6 -> 355 | C5: =Meterstanden!K19 -> 302 | D5: =Meterstanden!K32 -> 268 | E5: =Meterstanden!K45 -> 273 | F5: =Meterstanden!K58 -> 317 | G5: =Meterstanden!K71 -> 336 | H5: =Meterstanden!K84 -> 314 | I5: 363 | J5: =Meterstanden!K110 -> 317 | K5: =Meterstanden!K123 -> 319 | L5: =Meterstanden!K136 -> 208
A6: April | B6: =Meterstanden!K7 -> 184 | C6: =Meterstanden!K20 -> 272 | D6: =Meterstanden!K33 -> 265 | E6: =Meterstanden!K46 -> 256 | F6: =Meterstanden!K59 -> 254 | G6: =Meterstanden!K72 -> 260 | H6: =Meterstanden!K85 -> 243 | I6: 363 | J6: =Meterstanden!K111 -> 341 | K6: =Meterstanden!K124 -> 261 | L6: =Meterstanden!K137 -> 137
A7: Mei | B7: =Meterstanden!K8 -> 282 | C7: =Meterstanden!K21 -> 305 | D7: =Meterstanden!K34 -> 271 | E7: =Meterstanden!K47 -> 247 | F7: =Meterstanden!K60 -> 236 | G7: =Meterstanden!K73 -> 240 | H7: =Meterstanden!K86 -> 250 | I7: 363 | J7: =Meterstanden!K112 -> 234 | K7: =Meterstanden!K125 -> 214 | L7: =Meterstanden!K138 -> 100
A8: Juni | B8: =Meterstanden!K9 -> 282 | C8: =Meterstanden!K22 -> 290 | D8: =Meterstanden!K35 -> 260 | E8: =Meterstanden!K48 -> 111 | F8: =Meterstanden!K61 -> 258 | G8: =Meterstanden!K74 -> 241 | H8: =Meterstanden!K87 -> 232 | I8: =Meterstanden!K100 -> 230 | J8: =Meterstanden!K113 -> 266 | K8: =Meterstanden!K126 -> 147 | L8: =Meterstanden!K139 -> 100
A9: Juli | B9: =Meterstanden!K10 -> 282 | C9: =Meterstanden!K23 -> 209 | D9: =Meterstanden!K36 -> 254 | E9: =Meterstanden!K49 -> 216 | F9: =Meterstanden!K62 -> 218 | G9: =Meterstanden!K75 -> 258 | H9: =Meterstanden!K88 -> 239 | I9: =Meterstanden!K101 -> 211 | J9: =Meterstanden!K114 -> 235 | K9: =Meterstanden!K127 -> 64 | L9: =Meterstanden!K140 -> 96
A10: Augustus | B10: =Meterstanden!K11 -> 304 | C10: =Meterstanden!K24 -> 293 | D10: =Meterstanden!K37 -> 305 | E10: =Meterstanden!K50 -> 228 | F10: =Meterstanden!K63 -> 220 | G10: =Meterstanden!K76 -> 224 | H10: =Meterstanden!K89 -> 258 | I10: =Meterstanden!K102 -> 241 | J10: =Meterstanden!K115 -> 226 | K10: =Meterstanden!K128 -> 114 | L10: =Meterstanden!K141 -> 97
A11: September | B11: =Meterstanden!K12 -> 273 | C11: =Meterstanden!K25 -> 293 | D11: =Meterstanden!K38 -> 280 | E11: =Meterstanden!K51 -> 230 | F11: =Meterstanden!K64 -> 266 | G11: =Meterstanden!K77 -> 225 | H11: =Meterstanden!K90 -> 231 | I11: =Meterstanden!K103 -> 254 | J11: =Meterstanden!K116 -> 219 | K11: =Meterstanden!K129 -> 120 | L11: =Meterstanden!K142 -> 124
A12: Oktober | B12: =Meterstanden!K13 -> 304 | C12: =Meterstanden!K26 -> 304 | D12: =Meterstanden!K39 -> 275 | E12: =Meterstanden!K52 -> 238 | F12: =Meterstanden!K65 -> 269 | G12: =Meterstanden!K78 -> 251 | H12: =Meterstanden!K91 -> 316 | I12: =Meterstanden!K104 -> 336 | J12: =Meterstanden!K117 -> 264 | K12: =Meterstanden!K130 -> 200 | L12: =Meterstanden!K143 -> 159
A13: November | B13: =Meterstanden!K14 -> 355 | C13: =Meterstanden!K27 -> 303 | D13: =Meterstanden!K40 -> 283 | E13: =Meterstanden!K53 -> 248 | F13: =Meterstanden!K66 -> 331 | G13: =Meterstanden!K79 -> 324 | H13: =Meterstanden!K92 -> 359 | I13: =Meterstanden!K105 -> 374 | J13: =Meterstanden!K118 -> 287 | K13: =Meterstanden!K131 -> 271 | L13: =Meterstanden!K144 -> 250
A14: December | B14: =Meterstanden!K15 -> 349 | C14: =Meterstanden!K28 -> 369 | D14: =Meterstanden!K41 -> 317 | E14: =Meterstanden!K54 -> 307 | F14: =Meterstanden!K67 -> 379 | G14: =Meterstanden!K80 -> 412 | H14: =Meterstanden!K93 -> 403 | I14: =Meterstanden!K106 -> 457 | J14: =Meterstanden!K119 -> 340 | K14: =Meterstanden!K132 -> 351 | L14: =Meterstanden!K145 -> 335
B16: GAS
B17: 2014 | C17: 2015 | D17: 2016 | E17: 2017 | F17: 2018 | G17: 2019 | H17: 2020 | I17: 2021 | J17: 2022 | K17: 2023 | L17: 2024
A18: Januari | B18: =Meterstanden!N4 -> 226 | C18: =Meterstanden!N17 -> 288 | D18: =Meterstanden!N30 -> 220 | E18: =Meterstanden!N43 -> 243 | F18: =Meterstanden!N43 -> 243 | G18: =Meterstanden!N69 -> 263 | H18: =Meterstanden!N82 -> 195 | I18: 115 | J18: =Meterstanden!N108 -> 116 | K18: =Meterstanden!N121 -> 65 | L18: =Meterstanden!N134 -> 90
A19: Februari | B19: =Meterstanden!N5 -> 161 | C19: =Meterstanden!N18 -> 194 | D19: =Meterstanden!N31 -> 192 | E19: =Meterstanden!N44 -> 190 | F19: =Meterstanden!N44 -> 190 | G19: =Meterstanden!N70 -> 163 | H19: =Meterstanden!N83 -> 218 | I19: 115 | J19: =Meterstanden!N109 -> 122 | K19: =Meterstanden!N122 -> 48 | L19: =Meterstanden!N135 -> 47
A20: Maart | B20: =Meterstanden!N6 -> 117 | C20: =Meterstanden!N19 -> 199 | D20: =Meterstanden!N32 -> 175 | E20: =Meterstanden!N45 -> 160 | F20: =Meterstanden!N45 -> 160 | G20: =Meterstanden!N71 -> 150 | H20: =Meterstanden!N84 -> 110 | I20: 115 | J20: =Meterstanden!N110 -> 96 | K20: =Meterstanden!N123 -> 67 | L20: =Meterstanden!N136 -> 44
A21: April | B21: =Meterstanden!N7 -> 47 | C21: =Meterstanden!N20 -> 81 | D21: =Meterstanden!N33 -> 117 | E21: =Meterstanden!N46 -> 134 | F21: =Meterstanden!N46 -> 134 | G21: =Meterstanden!N72 -> 98 | H21: =Meterstanden!N85 -> 73 | I21: 114 | J21: =Meterstanden!N111 -> 66 | K21: =Meterstanden!N124 -> 46 | L21: =Meterstanden!N137 -> 26
A22: Mei | B22: =Meterstanden!N8 -> 38 | C22: =Meterstanden!N21 -> 50 | D22: =Meterstanden!N34 -> 48 | E22: =Meterstanden!N47 -> 46 | F22: =Meterstanden!N47 -> 46 | G22: =Meterstanden!N73 -> 51 | H22: =Meterstanden!N86 -> 46 | I22: 114 | J22: =Meterstanden!N112 -> 19 | K22: =Meterstanden!N125 -> 14 | L22: =Meterstanden!N138 -> 9
A23: Juni | B23: =Meterstanden!N9 -> 35 | C23: =Meterstanden!N22 -> 32 | D23: =Meterstanden!N35 -> 34 | E23: =Meterstanden!N48 -> 8 | F23: =Meterstanden!N48 -> 8 | G23: =Meterstanden!N74 -> 52 | H23: =Meterstanden!N87 -> 23 | I23: =Meterstanden!N100 -> 1 | J23: =Meterstanden!N113 -> 10 | K23: =Meterstanden!N126 -> 6 | L23: =Meterstanden!N139 -> 9
A24: Juli | B24: =Meterstanden!N10 -> 28 | C24: =Meterstanden!N23 -> 18 | D24: =Meterstanden!N36 -> 25 | E24: =Meterstanden!N49 -> 12 | F24: =Meterstanden!N49 -> 12 | G24: =Meterstanden!N75 -> 21 | H24: =Meterstanden!N88 -> 23 | I24: =Meterstanden!N101 -> 34 | J24: =Meterstanden!N114 -> 10 | K24: =Meterstanden!N127 -> 5 | L24: =Meterstanden!N140 -> 9
A25: Augustus | B25: =Meterstanden!N11 -> 26 | C25: =Meterstanden!N24 -> 36 | D25: =Meterstanden!N37 -> 34 | E25: =Meterstanden!N50 -> 14 | F25: =Meterstanden!N50 -> 14 | G25: =Meterstanden!N76 -> 31 | H25: =Meterstanden!N89 -> 27 | I25: =Meterstanden!N102 -> 17 | J25: =Meterstanden!N115 -> 14 | K25: =Meterstanden!N128 -> 11 | L25: =Meterstanden!N141 -> 8
A26: September | B26: =Meterstanden!N12 -> 27 | C26: =Meterstanden!N25 -> 37 | D26: =Meterstanden!N38 -> 29 | E26: =Meterstanden!N51 -> 43 | F26: =Meterstanden!N51 -> 43 | G26: =Meterstanden!N77 -> 32 | H26: =Meterstanden!N90 -> 58 | I26: =Meterstanden!N103 -> 20 | J26: =Meterstanden!N116 -> 11 | K26: =Meterstanden!N129 -> 9 | L26: =Meterstanden!N142 -> 8
A27: Oktober | B27: =Meterstanden!N13 -> 46 | C27: =Meterstanden!N26 -> 88 | D27: =Meterstanden!N39 -> 105 | E27: =Meterstanden!N52 -> 108 | F27: =Meterstanden!N52 -> 108 | G27: =Meterstanden!N78 -> 106 | H27: =Meterstanden!N91 -> 124 | I27: =Meterstanden!N104 -> 66 | J27: =Meterstanden!N117 -> 12 | K27: =Meterstanden!N130 -> 14 | L27: =Meterstanden!N143 -> 29
A28: November | B28: =Meterstanden!N14 -> 199 | C28: =Meterstanden!N27 -> 95 | D28: =Meterstanden!N40 -> 155 | E28: =Meterstanden!N53 -> 185 | F28: =Meterstanden!N53 -> 185 | G28: =Meterstanden!N79 -> 167 | H28: =Meterstanden!N92 -> 167 | I28: =Meterstanden!N105 -> 125 | J28: =Meterstanden!N118 -> 21 | K28: =Meterstanden!N131 -> 42 | L28: =Meterstanden!N144 -> 92
A29: December | B29: =Meterstanden!N15 -> 140 | C29: =Meterstanden!N28 -> 107 | D29: =Meterstanden!N41 -> 160 | E29: =Meterstanden!N54 -> 192 | F29: =Meterstanden!N54 -> 192 | G29: =Meterstanden!N80 -> 182 | H29: =Meterstanden!N93 -> 202 | I29: =Meterstanden!N106 -> 152 | J29: =Meterstanden!N119 -> 60 | K29: =Meterstanden!N132 -> 67 | L29: =Meterstanden!N145 -> 115
B31: Water
B32: 2014 | C32: 2015 | D32: 2016 | E32: 2017 | F32: 2018 | G32: 2019 | H32: 2020 | I32: 2021 | J32: 2022 | K32: 2023 | L32: 2024
A33: Januari | B33: =Meterstanden!O4 -> 11 | C33: =Meterstanden!O17 -> 12 | D33: =Meterstanden!O30 -> 14 | E33: =Meterstanden!O43 -> 13 | F33: =Meterstanden!O43 -> 13 | G33: =Meterstanden!O69 -> 8 | H33: =Meterstanden!O82 -> 8 | I33: =Meterstanden!O95 -> 9 | J33: =Meterstanden!O108 -> 9 | K33: =Meterstanden!O121 -> 6 | L33: =Meterstanden!O134 -> 6
A34: Februari | B34: =Meterstanden!O5 -> 13 | C34: =Meterstanden!O18 -> 10 | D34: =Meterstanden!O31 -> 13 | E34: =Meterstanden!O44 -> 12 | F34: =Meterstanden!O44 -> 12 | G34: =Meterstanden!O70 -> 7 | H34: =Meterstanden!O83 -> 9 | I34: =Meterstanden!O96 -> 9 | J34: =Meterstanden!O109 -> 9 | K34: =Meterstanden!O122 -> 5 | L34: =Meterstanden!O135 -> 6
A35: Maart | B35: =Meterstanden!O6 -> 11 | C35: =Meterstanden!O19 -> 11 | D35: =Meterstanden!O32 -> 13 | E35: =Meterstanden!O45 -> 14 | F35: =Meterstanden!O45 -> 14 | G35: =Meterstanden!O71 -> 11 | H35: =Meterstanden!O84 -> 10 | I35: =Meterstanden!O97 -> 9 | J35: =Meterstanden!O110 -> 7 | K35: =Meterstanden!O123 -> 6 | L35: =Meterstanden!O136 -> 6
A36: April | B36: =Meterstanden!O7 -> 13 | C36: =Meterstanden!O20 -> 10 | D36: =Meterstanden!O33 -> 14 | E36: =Meterstanden!O46 -> 13 | F36: =Meterstanden!O46 -> 13 | G36: =Meterstanden!O72 -> 8 | H36: =Meterstanden!O85 -> 10 | I36: =Meterstanden!O98 -> 9 | J36: =Meterstanden!O111 -> 8 | K36: =Meterstanden!O124 -> 6 | L36: =Meterstanden!O137 -> 7
A37: Mei | B37: =Meterstanden!O8 -> 14 | C37: =Meterstanden!O21 -> 12 | D37: =Meterstanden!O34 -> 14 | E37: =Meterstanden!O47 -> 9 | F37: =Meterstanden!O47 -> 9 | G37: =Meterstanden!O73 -> 7 | H37: =Meterstanden!O86 -> 8 | I37: =Meterstanden!O99 -> 11 | J37: =Meterstanden!O112 -> 10 | K37: =Meterstanden!O125 -> 6 | L37: =Meterstanden!O138 -> 5
A38: Juni | B38: =Meterstanden!O9 -> 14 | C38: =Meterstanden!O22 -> 12 | D38: =Meterstanden!O35 -> 13 | E38: =Meterstanden!O48 -> 7 | F38: =Meterstanden!O48 -> 7 | G38: =Meterstanden!O74 -> 8 | H38: =Meterstanden!O87 -> 9 | I38: =Meterstanden!O100 -> 9 | J38: =Meterstanden!O113 -> 6 | K38: =Meterstanden!O126 -> 6 | L38: =Meterstanden!O139 -> 6
A39: Juli | B39: =Meterstanden!O10 -> 12 | C39: =Meterstanden!O23 -> 8 | D39: =Meterstanden!O36 -> 12 | E39: =Meterstanden!O49 -> 7 | F39: =Meterstanden!O49 -> 7 | G39: =Meterstanden!O75 -> 8 | H39: =Meterstanden!O88 -> 10 | I39: =Meterstanden!O101 -> 9 | J39: =Meterstanden!O114 -> 8 | K39: =Meterstanden!O127 -> 3 | L39: =Meterstanden!O140 -> 5
A40: Augustus | B40: =Meterstanden!O11 -> 11 | C40: =Meterstanden!O24 -> 12 | D40: =Meterstanden!O37 -> 17 | E40: =Meterstanden!O50 -> 7 | F40: =Meterstanden!O50 -> 7 | G40: =Meterstanden!O76 -> 6 | H40: =Meterstanden!O89 -> 11 | I40: =Meterstanden!O102 -> 8 | J40: =Meterstanden!O115 -> 9 | K40: =Meterstanden!O128 -> 7 | L40: =Meterstanden!O141 -> 6
A41: September | B41: =Meterstanden!O12 -> 10 | C41: =Meterstanden!O25 -> 12 | D41: =Meterstanden!O38 -> 12 | E41: =Meterstanden!O51 -> 6 | F41: =Meterstanden!O51 -> 6 | G41: =Meterstanden!O77 -> 7 | H41: =Meterstanden!O90 -> 9 | I41: =Meterstanden!O103 -> 8 | J41: =Meterstanden!O116 -> 6 | K41: =Meterstanden!O129 -> 6 | L41: =Meterstanden!O142 -> 5
A42: Oktober | B42: =Meterstanden!O13 -> 12 | C42: =Meterstanden!O26 -> 14 | D42: =Meterstanden!O39 -> 15 | E42: =Meterstanden!O52 -> 8 | F42: =Meterstanden!O52 -> 8 | G42: =Meterstanden!O78 -> 9 | H42: =Meterstanden!O91 -> 9 | I42: =Meterstanden!O104 -> 8 | J42: =Meterstanden!O117 -> 8 | K42: =Meterstanden!O130 -> 6 | L42: =Meterstanden!O143 -> 6
...
